Workbook

Sheet Ops
A1: Новые строки добавляйте только под таблицей. Даты вводите в формате даты Excel.
A3: Дата | B3: Операция | C3: Статья | D3: Поступления | E3: Списания | F3: Чистый поток | G3: Год | H3: Месяц | I3: Квартал
A4: 01.04.2026 | B4: Поступление | C4: Оплата от покупателя | D4: 31440 | F4: =D4-E4 -> 31440 | G4: =YEAR(A4) -> 2026 | H4: =MONTH(A4) -> 4 | I4: =ROUNDUP(H4/3,0) -> 2
A5: 01.04.2026 | B5: Поступление | C5: Оплата от покупателя | D5: 13622 | F5: =D5-E5 -> 13622 | G5: =YEAR(A5) -> 2026 | H5: =MONTH(A5) -> 4 | I5: =ROUNDUP(H5/3,0) -> 2
A6: 01.04.2026 | B6: Поступление | C6: Оплата от покупателя | D6: 13795 | F6: =D6-E6 -> 13795 | G6: =YEAR(A6) -> 2026 | H6: =MONTH(A6) -> 4 | I6: =ROUNDUP(H6/3,0) -> 2
A7: 01.04.2026 | B7: Поступление | C7: Оплата от покупателя | D7: 136955 | F7: =D7-E7 -> 136955 | G7: =YEAR(A7) -> 2026 | H7: =MONTH(A7) -> 4 | I7: =ROUNDUP(H7/3,0) -> 2
A8: 01.04.2026 | B8: Поступление | C8: перевод со счета на счет | D8: 4716 | F8: =D8-E8 -> 4716 | G8: =YEAR(A8) -> 2026 | H8: =MONTH(A8) -> 4 | I8: =ROUNDUP(H8/3,0) -> 2
A9: 01.04.2026 | B9: Поступление | C9: перевод со счета на счет | D9: 2043.3 | F9: =D9-E9 -> 2043.3 | G9: =YEAR(A9) -> 2026 | H9: =MONTH(A9) -> 4 | I9: =ROUNDUP(H9/3,0) -> 2
A10: 01.04.2026 | B10: Поступление | C10: перевод со счета на счет | D10: 2069.25 | F10: =D10-E10 -> 2069.25 | G10: =YEAR(A10) -> 2026 | H10: =MONTH(A10) -> 4 | I10: =ROUNDUP(H10/3,0) -> 2
A11: 01.04.2026 | B11: Поступление | C11: перевод со счета на счет | D11: 20543.25 | F11: =D11-E11 -> 20543.25 | G11: =YEAR(A11) -> 2026 | H11: =MONTH(A11) -> 4 | I11: =ROUNDUP(H11/3,0) -> 2
A12: 01.04.2026 | B12: Поступление | C12: Эквайринг | D12: 71636.58 | F12: =D12-E12 -> 71636.58 | G12: =YEAR(A12) -> 2026 | H12: =MONTH(A12) -> 4 | I12: =ROUNDUP(H12/3,0) -> 2
A13: 01.04.2026 | B13: Списание | C13: перевод со счета на счет | E13: 4716 | F13: =D13-E13 -> -4716 | G13: =YEAR(A13) -> 2026 | H13: =MONTH(A13) -> 4 | I13: =ROUNDUP(H13/3,0) -> 2
A14: 01.04.2026 | B14: Списание | C14: перевод со счета на счет | E14: 2043.3 | F14: =D14-E14 -> -2043.3 | G14: =YEAR(A14) -> 2026 | H14: =MONTH(A14) -> 4 | I14: =ROUNDUP(H14/3,0) -> 2
A15: 01.04.2026 | B15: Списание | C15: перевод со счета на счет | E15: 2069.25 | F15: =D15-E15 -> -2069.25 | G15: =YEAR(A15) -> 2026 | H15: =MONTH(A15) -> 4 | I15: =ROUNDUP(H15/3,0) -> 2
A16: 01.04.2026 | B16: Списание | C16: перевод со счета на счет | E16: 20543.25 | F16: =D16-E16 -> -20543.25 | G16: =YEAR(A16) -> 2026 | H16: =MONTH(A16) -> 4 | I16: =ROUNDUP(H16/3,0) -> 2
A17: 01.04.2026 | B17: Списание | C17: Коммунальные услуги | E17: 481.78 | F17: =D17-E17 -> -481.78 | G17: =YEAR(A17) -> 2026 | H17: =MONTH(A17) -> 4 | I17: =ROUNDUP(H17/3,0) -> 2
A18: 01.04.2026 | B18: Списание | C18: транспортно-экспедиционные услуги | E18: 912.2 | F18: =D18-E18 -> -912.2 | G18: =YEAR(A18) -> 2026 | H18: =MONTH(A18) -> 4 | I18: =ROUNDUP(H18/3,0) -> 2
A19: 01.04.2026 | B19: Списание | C19: Возврат кредита банку | E19: 117530.76 | F19: =D19-E19 -> -117530.76 | G19: =YEAR(A19) -> 2026 | H19: =MONTH(A19) -> 4 | I19: =ROUNDUP(H19/3,0) -> 2
A20: 02.04.2026 | B20: Поступление | C20: Оплата от покупателя | D20: 94450 | F20: =D20-E20 -> 94450 | G20: =YEAR(A20) -> 2026 | H20: =MONTH(A20) -> 4 | I20: =ROUNDUP(H20/3,0) -> 2
A21: 02.04.2026 | B21: Поступление | C21: Оплата от покупателя | D21: 53741.5 | F21: =D21-E21 -> 53741.5 | G21: =YEAR(A21) -> 2026 | H21: =MONTH(A21) -> 4 | I21: =ROUNDUP(H21/3,0) -> 2
A22: 02.04.2026 | B22: Поступление | C22: перевод со счета на счет | D22: 14167.5 | F22: =D22-E22 -> 14167.5 | G22: =YEAR(A22) -> 2026 | H22: =MONTH(A22) -> 4 | I22: =ROUNDUP(H22/3,0) -> 2
A23: 02.04.2026 | B23: Поступление | C23: перевод со счета на счет | D23: 8061.22 | F23: =D23-E23 -> 8061.22 | G23: =YEAR(A23) -> 2026 | H23: =MONTH(A23) -> 4 | I23: =ROUNDUP(H23/3,0) -> 2
A24: 02.04.2026 | B24: Поступление | C24: Эквайринг | D24: 5120.48 | F24: =D24-E24 -> 5120.48 | G24: =YEAR(A24) -> 2026 | H24: =MONTH(A24) -> 4 | I24: =ROUNDUP(H24/3,0) -> 2
A25: 02.04.2026 | B25: Списание | C25: перевод со счета на счет | E25: 14167.5 | F25: =D25-E25 -> -14167.5 | G25: =YEAR(A25) -> 2026 | H25: =MONTH(A25) -> 4 | I25: =ROUNDUP(H25/3,0) -> 2
A26: 02.04.2026 | B26: Списание | C26: Программное обеспечение, Каталоги, Лицензии | E26: 18900 | F26: =D26-E26 -> -18900 | G26: =YEAR(A26) -> 2026 | H26: =MONTH(A26) -> 4 | I26: =ROUNDUP(H26/3,0) -> 2
A27: 02.04.2026 | B27: Списание | C27: перевод со счета на счет | E27: 8061.22 | F27: =D27-E27 -> -8061.22 | G27: =YEAR(A27) -> 2026 | H27: =MONTH(A27) -> 4 | I27: =ROUNDUP(H27/3,0) -> 2
A28: 02.04.2026 | B28: Списание | C28: Услуги связи | E28: 3173.14 | F28: =D28-E28 -> -3173.14 | G28: =YEAR(A28) -> 2026 | H28: =MONTH(A28) -> 4 | I28: =ROUNDUP(H28/3,0) -> 2
A29: 02.04.2026 | B29: Списание | C29: Коммунальные услуги | E29: 2407.68 | F29: =D29-E29 -> -2407.68 | G29: =YEAR(A29) -> 2026 | H29: =MONTH(A29) -> 4 | I29: =ROUNDUP(H29/3,0) -> 2
A30: 02.04.2026 | B30: Списание | C30: Коммунальные услуги | E30: 6879.7 | F30: =D30-E30 -> -6879.7 | G30: =YEAR(A30) -> 2026 | H30: =MONTH(A30) -> 4 | I30: =ROUNDUP(H30/3,0) -> 2
A31: 02.04.2026 | B31: Списание | C31: Подотчет | E31: 650 | F31: =D31-E31 -> -650 | G31: =YEAR(A31) -> 2026 | H31: =MONTH(A31) -> 4 | I31: =ROUNDUP(H31/3,0) -> 2
A32: 03.04.2026 | B32: Поступление | C32: Оплата от покупателя | D32: 14112 | F32: =D32-E32 -> 14112 | G32: =YEAR(A32) -> 2026 | H32: =MONTH(A32) -> 4 | I32: =ROUNDUP(H32/3,0) -> 2
A33: 03.04.2026 | B33: Поступление | C33: перевод со счета на счет | D33: 2116.8 | F33: =D33-E33 -> 2116.8 | G33: =YEAR(A33) -> 2026 | H33: =MONTH(A33) -> 4 | I33: =ROUNDUP(H33/3,0) -> 2
A34: 03.04.2026 | B34: Поступление | C34: Эквайринг | D34: 2163.92 | F34: =D34-E34 -> 2163.92 | G34: =YEAR(A34) -> 2026 | H34: =MONTH(A34) -> 4 | I34: =ROUNDUP(H34/3,0) -> 2
A35: 03.04.2026 | B35: Списание | C35: перевод со счета на счет | E35: 2116.8 | F35: =D35-E35 -> -2116.8 | G35: =YEAR(A35) -> 2026 | H35: =MONTH(A35) -> 4 | I35: =ROUNDUP(H35/3,0) -> 2
A36: 03.04.2026 | B36: Списание | C36: Коммунальные услуги | E36: 963.56 | F36: =D36-E36 -> -963.56 | G36: =YEAR(A36) -> 2026 | H36: =MONTH(A36) -> 4 | I36: =ROUNDUP(H36/3,0) -> 2
A37: 03.04.2026 | B37: Списание | C37: материалы для производства | E37: 35775 | F37: =D37-E37 -> -35775 | G37: =YEAR(A37) -> 2026 | H37: =MONTH(A37) -> 4 | I37: =ROUNDUP(H37/3,0) -> 2
A38: 03.04.2026 | B38: Списание | C38: Услуги печати | E38: 40122 | F38: =D38-E38 -> -40122 | G38: =YEAR(A38) -> 2026 | H38: =MONTH(A38) -> 4 | I38: =ROUNDUP(H38/3,0) -> 2
A39: 05.04.2026 | B39: Списание | C39: Подотчет | E39: 1888.2 | F39: =D39-E39 -> -1888.2 | G39: =YEAR(A39) -> 2026 | H39: =MONTH(A39) -> 4 | I39: =ROUNDUP(H39/3,0) -> 2
A40: 06.04.2026 | B40: Поступление | C40: Оплата от покупателя | D40: 5250 | F40: =D40-E40 -> 5250 | G40: =YEAR(A40) -> 2026 | H40: =MONTH(A40) -> 4 | I40: =ROUNDUP(H40/3,0) -> 2
A41: 06.04.2026 | B41: Поступление | C41: Оплата от покупателя | D41: 8710 | F41: =D41-E41 -> 8710 | G41: =YEAR(A41) -> 2026 | H41: =MONTH(A41) -> 4 | I41: =ROUNDUP(H41/3,0) -> 2
...

Sheet Dash
A1: Дашборд ДДС
D2: Поступления | E2: Списания | F2: Чистый поток | G2: Остаток на конец
A3: Год | B3: 2026 | D3: =SUMIFS(Ops!$D:$D,Ops!$G:$G,$B$3) -> 80226191 | E3: =SUMIFS(Ops!$E:$E,Ops!$G:$G,$B$3) -> 81065607 | F3: =D3-E3 -> -839415.71 | G3: =B4+F3 -> 456872.77
A4: Начальный остаток | B4: 1296288.5 | D4: =SUMIFS(Ops!$D:$D,Ops!$G:$G,$B$3,Ops!$I:$I,1) -> 0 | E4: =SUMIFS(Ops!$E:$E,Ops!$G:$G,$B$3,Ops!$I:$I,1) -> 0 | F4: =D4-E4 -> 0 | G4: =B4+F4 -> 1296288.5
A5: Последняя дата в базе | B5: =MAX(Ops!$A:$A) -> 0 | D5: =SUMIFS(Ops!$D:$D,Ops!$G:$G,$B$3,Ops!$I:$I,2) -> 80226191 | E5: =SUMIFS(Ops!$E:$E,Ops!$G:$G,$B$3,Ops!$I:$I,2) -> 81065607 | F5: =D5-E5 -> -839415.71 | G5: =G4+F5 -> 456872.77
A6: Количество операций | B6: =COUNTIF(Ops!$A:$A,">0") -> 0 | D6: =SUMIFS(Ops!$D:$D,Ops!$G:$G,$B$3,Ops!$I:$I,3)+SUMIFS(Ops!$D:$D,Ops!$G:$G,$B$3,Ops!$I:$I,4) -> 0 | E6: =SUMIFS(Ops!$E:$E,Ops!$G:$G,$B$3,Ops!$I:$I,3)+SUMIFS(Ops!$E:$E,Ops!$G:$G,$B$3,Ops!$I:$I,4) -> 0 | F6: =D6-E6 -> 0 | G6: =G5+F6 -> 456872.77
A10: № | B10: Месяц | C10: Поступления | D10: Списания | E10: Чистый поток | F10: Остаток на конец | I10: Топ-10 статей поступлений | L10: Топ-10 статей списаний
A11: 1 | B11: Январь | C11: =SUMIFS(Ops!$D:$D,Ops!$G:$G,$B$3,Ops!$H:$H,A11) -> 0 | D11: =SUMIFS(Ops!$E:$E,Ops!$G:$G,$B$3,Ops!$H:$H,A11) -> 0 | E11: =C11-D11 -> 0 | F11: =$B$4+SUM($E$11:E11) -> 1296288.5 | I11: Статья | J11: Сумма | L11: Статья | M11: Сумма
A12: 2 | B12: Февраль | C12: =SUMIFS(Ops!$D:$D,Ops!$G:$G,$B$3,Ops!$H:$H,A12) -> 0 | D12: =SUMIFS(Ops!$E:$E,Ops!$G:$G,$B$3,Ops!$H:$H,A12) -> 0 | E12: =C12-D12 -> 0 | F12: =$B$4+SUM($E$11:E12) -> 1296288.5 | I12: Депозит | J12: 14000000 | L12: Депозит | M12: 4000000
A13: 3 | B13: Март | C13: =SUMIFS(Ops!$D:$D,Ops!$G:$G,$B$3,Ops!$H:$H,A13) -> 0 | D13: =SUMIFS(Ops!$E:$E,Ops!$G:$G,$B$3,Ops!$H:$H,A13) -> 0 | E13: =C13-D13 -> 0 | F13: =$B$4+SUM($E$11:E13) -> 1296288.5 | I13: Оплата от покупателя | J13: 3204561.2 | L13: материалы для производства | M13: 969078.16
A14: 4 | B14: Апрель | C14: =SUMIFS(Ops!$D:$D,Ops!$G:$G,$B$3,Ops!$H:$H,A14) -> 18560380 | D14: =SUMIFS(Ops!$E:$E,Ops!$G:$G,$B$3,Ops!$H:$H,A14) -> 18105118 | E14: =C14-D14 -> 455262.38 | F14: =$B$4+SUM($E$11:E14) -> 1751550.9 | I14: перевод со счета на счет | J14: 682550.18 | L14: перевод со счета на счет | M14: 615013.62
A15: 5 | B15: Май | C15: =SUMIFS(Ops!$D:$D,Ops!$G:$G,$B$3,Ops!$H:$H,A15) -> 61665811 | D15: =SUMIFS(Ops!$E:$E,Ops!$G:$G,$B$3,Ops!$H:$H,A15) -> 62960489 | E15: =C15-D15 -> -1294678.1 | F15: =$B$4+SUM($E$11:E15) -> 456872.77 | I15: Эквайринг | J15: 338668.9 | L15: НДС | M15: 442938
A16: 6 | B16: Июнь | C16: =SUMIFS(Ops!$D:$D,Ops!$G:$G,$B$3,Ops!$H:$H,A16) -> 0 | D16: =SUMIFS(Ops!$E:$E,Ops!$G:$G,$B$3,Ops!$H:$H,A16) -> 0 | E16: =C16-D16 -> 0 | F16: =$B$4+SUM($E$11:E16) -> 456872.77 | I16: Возврат займа контрагентом | J16: 204000 | L16: Перечисление дивидендов | M16: 400000
A17: 7 | B17: Июль | C17: =SUMIFS(Ops!$D:$D,Ops!$G:$G,$B$3,Ops!$H:$H,A17) -> 0 | D17: =SUMIFS(Ops!$E:$E,Ops!$G:$G,$B$3,Ops!$H:$H,A17) -> 0 | E17: =C17-D17 -> 0 | F17: =$B$4+SUM($E$11:E17) -> 456872.77 | I17: Выплата процентов по депозиту | J17: 128206.02 | L17: Товар | M17: 227024.2
A18: 8 | B18: Август | C18: =SUMIFS(Ops!$D:$D,Ops!$G:$G,$B$3,Ops!$H:$H,A18) -> 0 | D18: =SUMIFS(Ops!$E:$E,Ops!$G:$G,$B$3,Ops!$H:$H,A18) -> 0 | E18: =C18-D18 -> 0 | F18: =$B$4+SUM($E$11:E18) -> 456872.77 | I18: Прочее поступление | J18: 2180 | L18: Налоги на персонал | M18: 149194
A19: 9 | B19: Сентябрь | C19: =SUMIFS(Ops!$D:$D,Ops!$G:$G,$B$3,Ops!$H:$H,A19) -> 0 | D19: =SUMIFS(Ops!$E:$E,Ops!$G:$G,$B$3,Ops!$H:$H,A19) -> 0 | E19: =C19-D19 -> 0 | F19: =$B$4+SUM($E$11:E19) -> 456872.77 | I19: Возврат от поставщика | J19: 214 | L19: упаковка | M19: 123002
A20: 10 | B20: Октябрь | C20: =SUMIFS(Ops!$D:$D,Ops!$G:$G,$B$3,Ops!$H:$H,A20) -> 0 | D20: =SUMIFS(Ops!$E:$E,Ops!$G:$G,$B$3,Ops!$H:$H,A20) -> 0 | E20: =C20-D20 -> 0 | F20: =$B$4+SUM($E$11:E20) -> 456872.77 | L20: Возврат кредита банку | M20: 117530.76
A21: 11 | B21: Ноябрь | C21: =SUMIFS(Ops!$D:$D,Ops!$G:$G,$B$3,Ops!$H:$H,A21) -> 0 | D21: =SUMIFS(Ops!$E:$E,Ops!$G:$G,$B$3,Ops!$H:$H,A21) -> 0 | E21: =C21-D21 -> 0 | F21: =$B$4+SUM($E$11:E21) -> 456872.77 | L21: Товар, материал медаль шоколадная | M21: 98000
A22: 12 | B22: Декабрь | C22: =SUMIFS(Ops!$D:$D,Ops!$G:$G,$B$3,Ops!$H:$H,A22) -> 0 | D22: =SUMIFS(Ops!$E:$E,Ops!$G:$G,$B$3,Ops!$H:$H,A22) -> 0 | E22: =C22-D22 -> 0 | F22: =$B$4+SUM($E$11:E22) -> 456872.77
B23: Итого | C23: =SUM(C11:C22) -> 80226191 | D23: =SUM(D11:D22) -> 81065607 | E23: =SUM(E11:E22) -> -839415.71 | F23: =F22 -> 456872.77
A26: Новые операции добавляйте на листе 'Операции' под таблицей. Дата должна быть датой Excel. Если дашборд не обновился сразу, нажмите Ctrl+Alt+F9.
